Workbook

Sheet machine_failure_dataset1
A1: Temperature | B1: Vibration | C1: Power_Usage | D1: Humidity | E1: Machine_Type | F1: Failure_Risk | H1: Sorted Temp | I1: Rank | J1: Percentile | K1: Expected Z-Score | M1: BIN | N1: Frequecy | O1: PDF
A2: 74.967142 | B2: 56.996777 | C2: 8.6496434 | D2: 20.460962 | E2: Mill | F2: 1 | H2: 37.587327 | I2: 1 | J2: =(I2 - 0.5) / 1000 -> 0.0005 | K2: =_xlfn.NORM.S.INV(J2) -> -3.2905267 | M2: 40 | N2: {=FREQUENCY(A2:A1001, M2:M16)} -> 1 | O2: =_xlfn.NORM.DIST(M2, 70.193, 9.792, FALSE) -> 0.000351152 | R2: GenAI Acknowledgment
A3: 68.617357 | B3: 54.623168 | C3: 9.7109627 | D3: 25.698075 | E3: Lathe | F3: 0 | H3: 43.031134 | I3: 2 | J3: =(I3 - 0.5) / 1000 -> 0.0015 | K3: =_xlfn.NORM.S.INV(J3) -> -2.9677379 | M3: 45 | N3: 3 | O3: =_xlfn.NORM.DIST(M3, 70.193, 9.792, FALSE) -> 0.0014881946
A4: 76.476885 | B4: 50.298152 | C4: 8.4151602 | D4: 27.931972 | E4: Drill | F4: 1 | H4: 43.490302 | I4: 3 | J4: =(I4 - 0.5) / 1000 -> 0.0025 | K4: =_xlfn.NORM.S.INV(J4) -> -2.8070338 | M4: 50 | N4: 13 | O4: =_xlfn.NORM.DIST(M4, 70.193, 9.792, FALSE) -> 0.0048594718
A5: 85.230299 | B5: 46.765316 | C5: 9.3840769 | D5: 39.438438 | E5: Lathe | F5: 1 | H5: 43.802549 | I5: 4 | J5: =(I5 - 0.5) / 1000 -> 0.0035 | K5: =_xlfn.NORM.S.INV(J5) -> -2.6968443 | M5: 55 | N5: 40 | O5: =_xlfn.NORM.DIST(M5, 70.193, 9.792, FALSE) -> 0.012225966
A6: 67.658466 | B6: 53.491117 | C6: 6.2127707 | D6: 32.782766 | E6: Drill | F6: 1 | H6: 45.283555 | I6: 5 | J6: =(I6 - 0.5) / 1000 -> 0.0045 | K6: =_xlfn.NORM.S.INV(J6) -> -2.6120541 | M6: 60 | N6: 90 | O6: =_xlfn.NORM.DIST(M6, 70.193, 9.792, FALSE) -> 0.02369966
A7: 67.65863 | B7: 51.967427 | C7: 10.426587 | D7: 23.322592 | E7: Drill | F7: 0 | H7: 45.761207 | I7: 6 | J7: =(I7 - 0.5) / 1000 -> 0.0055 | K7: =_xlfn.NORM.S.INV(J7) -> -2.5426988 | M7: 65 | N7: 166 | O7: =_xlfn.NORM.DIST(M7, 70.193, 9.792, FALSE) -> 0.035396948
A8: 85.792128 | B8: 54.475966 | C8: 10.002411 | D8: 32.430181 | E8: Lathe | F8: 0 | H8: 46.980788 | I8: 7 | J8: =(I8 - 0.5) / 1000 -> 0.0065 | K8: =_xlfn.NORM.S.INV(J8) -> -2.4837693 | M8: 70 | N8: 177 | O8: =_xlfn.NORM.DIST(M8, 70.193, 9.792, FALSE) -> 0.040733742
A9: 77.674347 | B9: 53.175859 | C9: 8.3658227 | D9: 22.26348 | E9: Mill | F9: 1 | H9: 47.888647 | I9: 8 | J9: =(I9 - 0.5) / 1000 -> 0.0075 | K9: =_xlfn.NORM.S.INV(J9) -> -2.4323791 | M9: 75 | N9: 204 | O9: =_xlfn.NORM.DIST(M9, 70.193, 9.792, FALSE) -> 0.036116659
A10: 65.305256 | B10: 55.247764 | C10: 11.318491 | D10: 35.413455 | E10: Drill | F10: 0 | H10: 48.01194 | I10: 9 | J10: =(I10 - 0.5) / 1000 -> 0.0085 | K10: =_xlfn.NORM.S.INV(J10) -> -2.3867077 | M10: 80 | N10: 151 | O10: =_xlfn.NORM.DIST(M10, 70.193, 9.792, FALSE) -> 0.024673209 | R10: Task 1
A11: 75.4256 | B11: 47.323824 | C11: 11.87514 | D11: 27.644377 | E11: Mill | F11: 1 | H11: 48.761043 | I11: 10 | J11: =(I11 - 0.5) / 1000 -> 0.0095 | K11: =_xlfn.NORM.S.INV(J11) -> -2.345531 | M11: 85 | N11: 80 | O11: =_xlfn.NORM.DIST(M11, 70.193, 9.792, FALSE) -> 0.012986989 | R11: Continous Variable | T11: Temperature
A12: 65.365823 | B12: 56.58697 | C12: 6.7848803 | D12: 29.531819 | E12: Lathe | F12: 1 | H12: 49.180706 | I12: 11 | J12: =(I12 - 0.5) / 1000 -> 0.0105 | K12: =_xlfn.NORM.S.INV(J12) -> -2.3079845 | M12: 90 | N12: 51 | O12: =_xlfn.NORM.DIST(M12, 70.193, 9.792, FALSE) -> 0.0052669124 | R12: Max | T12: =MAX(A1:A1000) -> 108.52731
A13: 65.342702 | B13: 50.987998 | C13: 8.4745504 | D13: 36.628983 | E13: Drill | F13: 0 | H13: 49.266098 | I13: 12 | J13: =(I13 - 0.5) / 1000 -> 0.0115 | K13: =_xlfn.NORM.S.INV(J13) -> -2.2734347 | M13: 95 | N13: 17 | O13: =_xlfn.NORM.DIST(M13, 70.193, 9.792, FALSE) -> 0.0016457676 | R13: Min | T13: =MIN(A1:A1000) -> 37.587327
A14: 72.419623 | B14: 60.376304 | C14: 8.4617153 | D14: 23.564182 | E14: Lathe | F14: 0 | H14: 49.325579 | I14: 13 | J14: =(I14 - 0.5) / 1000 -> 0.0125 | K14: =_xlfn.NORM.S.INV(J14) -> -2.2414027 | M14: 100 | N14: 5 | O14: =_xlfn.NORM.DIST(M14, 70.193, 9.792, FALSE) -> 0.00039622849 | R14: Range = | S14: Max-Min = | T14: =T12-T13 -> 70.939988
A15: 50.867198 | B15: 46.554061 | C15: 8.1201938 | D15: 23.014409 | E15: Mill | F15: 1 | H15: 49.582651 | I15: 14 | J15: =(I15 - 0.5) / 1000 -> 0.0135 | K15: =_xlfn.NORM.S.INV(J15) -> -2.2115178 | M15: 105 | N15: 1 | O15: =_xlfn.NORM.DIST(M15, 70.193, 9.792, FALSE) -> 7.3500058e-05 | R15: Number of classes | T15: 10
A16: 52.750822 | B16: 58.679819 | C16: 11.65895 | D16: 27.082003 | E16: Lathe | F16: 0 | H16: 49.607678 | I16: 15 | J16: =(I16 - 0.5) / 1000 -> 0.0145 | K16: =_xlfn.NORM.S.INV(J16) -> -2.1834865 | M16: 110 | N16: 1 | O16: =_xlfn.NORM.DIST(M16, 70.193, 9.792, FALSE) -> 1.0504961e-05 | R16: Class Width | T16: =T14/10 -> 7.0939988 | U16: ≈ 8
A17: 64.377125 | B17: 50.989554 | C17: 9.6123477 | D17: 35.191894 | E17: Lathe | F17: 0 | H17: 49.618755 | I17: 16 | J17: =(I17 - 0.5) / 1000 -> 0.0155 | K17: =_xlfn.NORM.S.INV(J17) -> -2.1570727 | N17: 0
A18: 59.871689 | B18: 46.74291 | C18: 9.4709703 | D18: 22.40327 | E18: Drill | F18: 0 | H18: 49.748574 | I18: 17 | J18: =(I18 - 0.5) / 1000 -> 0.0165 | K18: =_xlfn.NORM.S.INV(J18) -> -2.1320833
A19: 73.142473 | B19: 47.580571 | C19: 5.9922753 | D19: 15.839222 | E19: Lathe | F19: 0 | H19: 50.124311 | I19: 18 | J19: =(I19 - 0.5) / 1000 -> 0.0175 | K19: =_xlfn.NORM.S.INV(J19) -> -2.1083584
A20: 60.919759 | B20: 48.398263 | C20: 11.270836 | D20: 27.744206 | E20: Lathe | F20: 1 | H20: 50.403299 | I20: 19 | J20: =(I20 - 0.5) / 1000 -> 0.0185 | K20: =_xlfn.NORM.S.INV(J20) -> -2.0857641 | V20: Histogram
A21: 55.876963 | B21: 52.12083 | C21: 7.5214832 | D21: 32.758704 | E21: Lathe | F21: 0 | H21: 50.479122 | I21: 20 | J21: =(I21 - 0.5) / 1000 -> 0.0195 | K21: =_xlfn.NORM.S.INV(J21) -> -2.0641869
A22: 84.656488 | B22: 52.614177 | C22: 10.119865 | D22: 36.001309 | E22: Drill | F22: 0 | H22: 50.812288 | I22: 21 | J22: =(I22 - 0.5) / 1000 -> 0.0205 | K22: =_xlfn.NORM.S.INV(J22) -> -2.04353
A23: 67.742237 | B23: 47.1315 | C23: 10.554754 | D23: 27.684193 | E23: Mill | F23: 1 | H23: 50.867198 | I23: 22 | J23: =(I23 - 0.5) / 1000 -> 0.0215 | K23: =_xlfn.NORM.S.INV(J23) -> -2.02371
A24: 70.675282 | B24: 49.878227 | C24: 12.721317 | D24: 27.942867 | E24: Mill | F24: 1 | H24: 51.104593 | I24: 23 | J24: =(I24 - 0.5) / 1000 -> 0.0225 | K24: =_xlfn.NORM.S.INV(J24) -> -2.0046545
A25: 55.752518 | B25: 60.711352 | C25: 7.3823592 | D25: 35.769504 | E25: Lathe | F25: 0 | H25: 51.292081 | I25: 24 | J25: =(I25 - 0.5) / 1000 -> 0.0235 | K25: =_xlfn.NORM.S.INV(J25) -> -1.9863002
A26: 64.556173 | B26: 58.637716 | C26: 3.9609757 | D26: 20.651291 | E26: Drill | F26: 0 | H26: 51.327348 | I26: 25 | J26: =(I26 - 0.5) / 1000 -> 0.0245 | K26: =_xlfn.NORM.S.INV(J26) -> -1.9685917
A27: 71.109226 | B27: 52.181618 | C27: 10.367699 | D27: 28.057396 | E27: Lathe | F27: 0 | H27: 51.591258 | I27: 26 | J27: =(I27 - 0.5) / 1000 -> 0.0255 | K27: =_xlfn.NORM.S.INV(J27) -> -1.9514798
A28: 58.490064 | B28: 50.190017 | C28: 13.601022 | D28: 30.952119 | E28: Mill | F28: 0 | H28: 51.951179 | I28: 27 | J28: =(I28 - 0.5) / 1000 -> 0.0265 | K28: =_xlfn.NORM.S.INV(J28) -> -1.9349209
A29: 73.75698 | B29: 50.600157 | C29: 12.477893 | D29: 32.246094 | E29: Drill | F29: 1 | H29: 52.212798 | I29: 28 | J29: =(I29 - 0.5) / 1000 -> 0.0275 | K29: =_xlfn.NORM.S.INV(J29) -> -1.9188762
A30: 63.993613 | B30: 53.06759 | C30: 10.419319 | D30: 27.450967 | E30: Mill | F30: 0 | H30: 52.369598 | I30: 29 | J30: =(I30 - 0.5) / 1000 -> 0.0285 | K30: =_xlfn.NORM.S.INV(J30) -> -1.9033108
A31: 67.083062 | B31: 44.886037 | C31: 9.0167276 | D31: 30.172205 | E31: Mill | F31: 1 | H31: 52.412605 | I31: 30 | J31: =(I31 - 0.5) / 1000 -> 0.0295 | K31: =_xlfn.NORM.S.INV(J31) -> -1.8881933
A32: 63.982934 | B32: 48.713117 | C32: 11.614245 | D32: 17.558363 | E32: Drill | F32: 0 | H32: 52.750822 | I32: 31 | J32: =(I32 - 0.5) / 1000 -> 0.0305 | K32: =_xlfn.NORM.S.INV(J32) -> -1.8734955
... A40: 56.71814 | B40: 51.122259 | C40: 9.9488514 | D40: 25.186337 | E40: Mill | F40: 1 | H40: 53.390391 | I40: 39 | J40: =(I40 - 0.5) / 1000 -> 0.0385 | K40: =_xlfn.NORM.S.INV(J40) -> -1.7683644
A41: 71.968612 | B41: 55.235492 | C41: 6.4618482 | D41: 28.966944 | E41: Mill | F41: 1 | H41: 53.451433 | I41: 40 | J41: =(I41 - 0.5) / 1000 -> 0.0395 | K41: =_xlfn.NORM.S.INV(J41) -> -1.756518 | U41: Boxplot
A42: 77.384666 | B42: 58.419638 | C42: 8.6105737 | D42: 33.051081 | E42: Lathe | F42: 1 | H42: 53.724576 | I42: 41 | J42: =(I42 - 0.5) / 1000 -> 0.0405 | K42: =_xlfn.NORM.S.INV(J42) -> -1.7449131
A43: 71.713683 | B43: 47.705579 | C43: 9.1814351 | D43: 30.784865 | E43: Drill | F43: 0 | H43: 53.872841 | I43: 42 | J43: =(I43 - 0.5) / 1000 -> 0.0415 | K43: =_xlfn.NORM.S.INV(J43) -> -1.7335385
A44: 68.843517 | B44: 55.393404 | C44: 8.9518232 | D44: 27.067344 | E44: Lathe | F44: 0 | H44: 53.925168 | I44: 43 | J44: =(I44 - 0.5) / 1000 -> 0.0425 | K44: =_xlfn.NORM.S.INV(J44) -> -1.7223839
A45: 66.988963 | B45: 49.807458 | C45: 10.30471 | D45: 31.121082 | E45: Lathe | F45: 0 | H45: 53.935537 | I45: 44 | J45: =(I45 - 0.5) / 1000 -> 0.0435 | K45: =_xlfn.NORM.S.INV(J45) -> -1.7114396
A46: 55.21478 | B46: 49.136863 | C46: 8.3551601 | D46: 33.573049 | E46: Lathe | F46: 1 | H46: 54.055723 | I46: 45 | J46: =(I46 - 0.5) / 1000 -> 0.0445 | K46: =_xlfn.NORM.S.INV(J46) -> -1.7006965
A47: 62.801558 | B47: 54.4183 | C47: 12.242061 | D47: 19.750294 | E47: Lathe | F47: 1 | H47: 54.160972 | I47: 46 | J47: =(I47 - 0.5) / 1000 -> 0.0455 | K47: =_xlfn.NORM.S.INV(J47) -> -1.6901461
...

Sheet Sampling Distribution (n=5)
A1: 100 Samples of Size 5 | F1: Mean
A2: {=INDEX(machine_failure_dataset1!$A$2:$A$1001,RANDBETWEEN(1,1000))} -> 76.116763 | B2: {=INDEX(machine_failure_dataset1!$A$2:$A$1001, RANDBETWEEN(1, 1000))} -> 61.439162 | C2: {=INDEX(machine_failure_dataset1!$A$2:$A$1001, RANDBETWEEN(1, 1000))} -> 72.766908 | D2: {=INDEX(machine_failure_dataset1!$A$2:$A$1001, RANDBETWEEN(1, 1000))} -> 63.493574 | E2: {=INDEX(machine_failure_dataset1!$A$2:$A$1001, RANDBETWEEN(1, 1000))} -> 61.690499 | F2: =AVERAGE(A2:E2) -> 67.101381
A3: {=INDEX(machine_failure_dataset1!$A$2:$A$1001, RANDBETWEEN(1, 1000))} -> 72.274599 | B3: {=INDEX(machine_failure_dataset1!$A$2:$A$1001, RANDBETWEEN(1, 1000))} -> 85.931866 | C3: {=INDEX(machine_failure_dataset1!$A$2:$A$1001, RANDBETWEEN(1, 1000))} -> 73.61636 | D3: {=INDEX(machine_failure_dataset1!$A$2:$A$1001, RANDBETWEEN(1, 1000))} -> 59.18452 | E3: {=INDEX(machine_failure_dataset1!$A$2:$A$1001, RANDBETWEEN(1, 1000))} -> 67.272764 | F3: =AVERAGE(A3:E3) -> 71.656022
A4: {=INDEX(machine_failure_dataset1!$A$2:$A$1001, RANDBETWEEN(1, 1000))} -> 49.618755 | B4: {=INDEX(machine_failure_dataset1!$A$2:$A$1001, RANDBETWEEN(1, 1000))} -> 64.362754 | C4: {=INDEX(machine_failure_dataset1!$A$2:$A$1001, RANDBETWEEN(1, 1000))} -> 74.789798 | D4: {=INDEX(machine_failure_dataset1!$A$2:$A$1001, RANDBETWEEN(1, 1000))} -> 84.656488 | E4: {=INDEX(machine_failure_dataset1!$A$2:$A$1001, RANDBETWEEN(1, 1000))} -> 80.830512 | F4: =AVERAGE(A4:E4) -> 70.851662
A5: {=INDEX(machine_failure_dataset1!$A$2:$A$1001, RANDBETWEEN(1, 1000))} -> 84.437646 | B5: {=INDEX(machine_failure_dataset1!$A$2:$A$1001, RANDBETWEEN(1, 1000))} -> 78.135096 | C5: {=INDEX(machine_failure_dataset1!$A$2:$A$1001, RANDBETWEEN(1, 1000))} -> 80.309995 | D5: {=INDEX(machine_failure_dataset1!$A$2:$A$1001, RANDBETWEEN(1, 1000))} -> 75.150353 | E5: {=INDEX(machine_failure_dataset1!$A$2:$A$1001, RANDBETWEEN(1, 1000))} -> 56.483154 | F5: =AVERAGE(A5:E5) -> 74.903249
A6: {=INDEX(machine_failure_dataset1!$A$2:$A$1001, RANDBETWEEN(1, 1000))} -> 82.378163 | B6: {=INDEX(machine_failure_dataset1!$A$2:$A$1001, RANDBETWEEN(1, 1000))} -> 73.464482 | C6: {=INDEX(machine_failure_dataset1!$A$2:$A$1001, RANDBETWEEN(1, 1000))} -> 71.664522 | D6: {=INDEX(machine_failure_dataset1!$A$2:$A$1001, RANDBETWEEN(1, 1000))} -> 67.765372 | E6: {=INDEX(machine_failure_dataset1!$A$2:$A$1001, RANDBETWEEN(1, 1000))} -> 91.898029 | F6: =AVERAGE(A6:E6) -> 77.434114
A7: {=INDEX(machine_failure_dataset1!$A$2:$A$1001, RANDBETWEEN(1, 1000))} -> 66.078918 | B7: {=INDEX(machine_failure_dataset1!$A$2:$A$1001, RANDBETWEEN(1, 1000))} -> 76.748195 | C7: {=INDEX(machine_failure_dataset1!$A$2:$A$1001, RANDBETWEEN(1, 1000))} -> 70.818741 | D7: {=INDEX(machine_failure_dataset1!$A$2:$A$1001, RANDBETWEEN(1, 1000))} -> 67.658466 | E7: {=INDEX(machine_failure_dataset1!$A$2:$A$1001, RANDBETWEEN(1, 1000))} -> 78.524333 | F7: =AVERAGE(A7:E7) -> 71.965731
A8: {=INDEX(machine_failure_dataset1!$A$2:$A$1001, RANDBETWEEN(1, 1000))} -> 61.243817 | B8: {=INDEX(machine_failure_dataset1!$A$2:$A$1001, RANDBETWEEN(1, 1000))} -> 60.805758 | C8: {=INDEX(machine_failure_dataset1!$A$2:$A$1001, RANDBETWEEN(1, 1000))} -> 61.676444 | D8: {=INDEX(machine_failure_dataset1!$A$2:$A$1001, RANDBETWEEN(1, 1000))} -> 66.078918 | E8: {=INDEX(machine_failure_dataset1!$A$2:$A$1001, RANDBETWEEN(1, 1000))} -> 73.711459 | F8: =AVERAGE(A8:E8) -> 64.703279
A9: {=INDEX(machine_failure_dataset1!$A$2:$A$1001, RANDBETWEEN(1, 1000))} -> 59.299152 | B9: {=INDEX(machine_failure_dataset1!$A$2:$A$1001, RANDBETWEEN(1, 1000))} -> 85.380366 | C9: {=INDEX(machine_failure_dataset1!$A$2:$A$1001, RANDBETWEEN(1, 1000))} -> 52.412605 | D9: {=INDEX(machine_failure_dataset1!$A$2:$A$1001, RANDBETWEEN(1, 1000))} -> 64.231081 | E9: {=INDEX(machine_failure_dataset1!$A$2:$A$1001, RANDBETWEEN(1, 1000))} -> 88.467073 | F9: =AVERAGE(A9:E9) -> 69.958056
A10: {=INDEX(machine_failure_dataset1!$A$2:$A$1001, RANDBETWEEN(1, 1000))} -> 80.584245 | B10: {=INDEX(machine_failure_dataset1!$A$2:$A$1001, RANDBETWEEN(1, 1000))} -> 60.906125 | C10: {=INDEX(machine_failure_dataset1!$A$2:$A$1001, RANDBETWEEN(1, 1000))} -> 73.41756 | D10: {=INDEX(machine_failure_dataset1!$A$2:$A$1001, RANDBETWEEN(1, 1000))} -> 77.140005 | E10: {=INDEX(machine_failure_dataset1!$A$2:$A$1001, RANDBETWEEN(1, 1000))} -> 67.631814 | F10: =AVERAGE(A10:E10) -> 71.93595
A11: {=INDEX(machine_failure_dataset1!$A$2:$A$1001, RANDBETWEEN(1, 1000))} -> 85.795721 | B11: {=INDEX(machine_failure_dataset1!$A$2:$A$1001, RANDBETWEEN(1, 1000))} -> 64.084286 | C11: {=INDEX(machine_failure_dataset1!$A$2:$A$1001, RANDBETWEEN(1, 1000))} -> 71.220098 | D11: {=INDEX(machine_failure_dataset1!$A$2:$A$1001, RANDBETWEEN(1, 1000))} -> 76.329318 | E11: {=INDEX(machine_failure_dataset1!$A$2:$A$1001, RANDBETWEEN(1, 1000))} -> 70.287448 | F11: =AVERAGE(A11:E11) -> 73.543374
A12: {=INDEX(machine_failure_dataset1!$A$2:$A$1001, RANDBETWEEN(1, 1000))} -> 65.406391 | B12: {=INDEX(machine_failure_dataset1!$A$2:$A$1001, RANDBETWEEN(1, 1000))} -> 72.322537 | C12: {=INDEX(machine_failure_dataset1!$A$2:$A$1001, RANDBETWEEN(1, 1000))} -> 65.128746 | D12: {=INDEX(machine_failure_dataset1!$A$2:$A$1001, RANDBETWEEN(1, 1000))} -> 82.460852 | E12: {=INDEX(machine_failure_dataset1!$A$2:$A$1001, RANDBETWEEN(1, 1000))} -> 51.951179 | F12: =AVERAGE(A12:E12) -> 67.453941
A13: {=INDEX(machine_failure_dataset1!$A$2:$A$1001, RANDBETWEEN(1, 1000))} -> 91.531825 | B13: {=INDEX(machine_failure_dataset1!$A$2:$A$1001, RANDBETWEEN(1, 1000))} -> 82.776649 | C13: {=INDEX(machine_failure_dataset1!$A$2:$A$1001, RANDBETWEEN(1, 1000))} -> 66.573124 | D13: {=INDEX(machine_failure_dataset1!$A$2:$A$1001, RANDBETWEEN(1, 1000))} -> 70.245102 | E13: {=INDEX(machine_failure_dataset1!$A$2:$A$1001, RANDBETWEEN(1, 1000))} -> 61.915064 | F13: =AVERAGE(A13:E13) -> 74.608353
A14: {=INDEX(machine_failure_dataset1!$A$2:$A$1001, RANDBETWEEN(1, 1000))} -> 46.980788 | B14: {=INDEX(machine_failure_dataset1!$A$2:$A$1001, RANDBETWEEN(1, 1000))} -> 53.384799 | C14: {=INDEX(machine_failure_dataset1!$A$2:$A$1001, RANDBETWEEN(1, 1000))} -> 55.925362 | D14: {=INDEX(machine_failure_dataset1!$A$2:$A$1001, RANDBETWEEN(1, 1000))} -> 81.033019 | E14: {=INDEX(machine_failure_dataset1!$A$2:$A$1001, RANDBETWEEN(1, 1000))} -> 69.339202 | F14: =AVERAGE(A14:E14) -> 61.332634
... A101: {=INDEX(machine_failure_dataset1!$A$2:$A$1001, RANDBETWEEN(1, 1000))} -> 62.728628 | B101: {=INDEX(machine_failure_dataset1!$A$2:$A$1001, RANDBETWEEN(1, 1000))} -> 85.03993 | C101: {=INDEX(machine_failure_dataset1!$A$2:$A$1001, RANDBETWEEN(1, 1000))} -> 86.764373 | D101: {=INDEX(machine_failure_dataset1!$A$2:$A$1001, RANDBETWEEN(1, 1000))} -> 55.214138 | E101: {=INDEX(machine_failure_dataset1!$A$2:$A$1001, RANDBETWEEN(1, 1000))} -> 62.017028 | F101: =AVERAGE(A101:E101) -> 70.352819

Sheet Sampling Distribution (n=20)
L1: 100 sample of 20 | U1: Mean
A2: {=INDEX(machine_failure_dataset1!$A$2:$A$1001, RANDBETWEEN(1, 1000))} -> 68.14341 | B2: {=INDEX(machine_failure_dataset1!$A$2:$A$1001, RANDBETWEEN(1, 1000))} -> 57.778722 | C2: {=INDEX(machine_failure_dataset1!$A$2:$A$1001, RANDBETWEEN(1, 1000))} -> 63.483997 | D2: {=INDEX(machine_failure_dataset1!$A$2:$A$1001, RANDBETWEEN(1, 1000))} -> 54.851528 | E2: {=INDEX(machine_failure_dataset1!$A$2:$A$1001, RANDBETWEEN(1, 1000))} -> 62.923305 | F2: {=INDEX(machine_failure_dataset1!$A$2:$A$1001, RANDBETWEEN(1, 1000))} -> 71.965212 | G2: {=INDEX(machine_failure_dataset1!$A$2:$A$1001, RANDBETWEEN(1, 1000))} -> 72.436872 | H2: {=INDEX(machine_failure_dataset1!$A$2:$A$1001, RANDBETWEEN(1, 1000))} -> 69.339202 | ... T2: {=INDEX(machine_failure_dataset1!$A$2:$A$1001, RANDBETWEEN(1, 1000))} -> 66.572855 | U2: =AVERAGE(A2:T2) -> 68.423441
A3: {=INDEX(machine_failure_dataset1!$A$2:$A$1001, RANDBETWEEN(1, 1000))} -> 56.555495 | B3: {=INDEX(machine_failure_dataset1!$A$2:$A$1001, RANDBETWEEN(1, 1000))} -> 77.916627 | C3: {=INDEX(machine_failure_dataset1!$A$2:$A$1001, RANDBETWEEN(1, 1000))} -> 88.467073 | D3: {=INDEX(machine_failure_dataset1!$A$2:$A$1001, RANDBETWEEN(1, 1000))} -> 83.686316 | E3: {=INDEX(machine_failure_dataset1!$A$2:$A$1001, RANDBETWEEN(1, 1000))} -> 80.531529 | F3: {=INDEX(machine_failure_dataset1!$A$2:$A$1001, RANDBETWEEN(1, 1000))} -> 72.076877 | G3: {=INDEX(machine_failure_dataset1!$A$2:$A$1001, RANDBETWEEN(1, 1000))} -> 75.95157 | H3: {=INDEX(machine_failure_dataset1!$A$2:$A$1001, RANDBETWEEN(1, 1000))} -> 69.298343 | ... T3: {=INDEX(machine_failure_dataset1!$A$2:$A$1001, RANDBETWEEN(1, 1000))} -> 64.861331 | U3: =AVERAGE(A3:T3) -> 73.838967
A4: {=INDEX(machine_failure_dataset1!$A$2:$A$1001, RANDBETWEEN(1, 1000))} -> 57.049212 | B4: {=INDEX(machine_failure_dataset1!$A$2:$A$1001, RANDBETWEEN(1, 1000))} -> 74.591801 | C4: {=INDEX(machine_failure_dataset1!$A$2:$A$1001, RANDBETWEEN(1, 1000))} -> 81.355656 | D4: {=INDEX(machine_failure_dataset1!$A$2:$A$1001, RANDBETWEEN(1, 1000))} -> 54.768131 | E4: {=INDEX(machine_failure_dataset1!$A$2:$A$1001, RANDBETWEEN(1, 1000))} -> 55.214138 | F4: {=INDEX(machine_failure_dataset1!$A$2:$A$1001, RANDBETWEEN(1, 1000))} -> 74.924513 | G4: {=INDEX(machine_failure_dataset1!$A$2:$A$1001, RANDBETWEEN(1, 1000))} -> 72.034636 | H4: {=INDEX(machine_failure_dataset1!$A$2:$A$1001, RANDBETWEEN(1, 1000))} -> 77.462536 | ... T4: {=INDEX(machine_failure_dataset1!$A$2:$A$1001, RANDBETWEEN(1, 1000))} -> 67.860112 | U4: =AVERAGE(A4:T4) -> 70.379509
A5: {=INDEX(machine_failure_dataset1!$A$2:$A$1001, RANDBETWEEN(1, 1000))} -> 66.904536 | B5: {=INDEX(machine_failure_dataset1!$A$2:$A$1001, RANDBETWEEN(1, 1000))} -> 71.503018 | C5: {=INDEX(machine_failure_dataset1!$A$2:$A$1001, RANDBETWEEN(1, 1000))} -> 64.691312 | D5: {=INDEX(machine_failure_dataset1!$A$2:$A$1001, RANDBETWEEN(1, 1000))} -> 74.567532 | E5: {=INDEX(machine_failure_dataset1!$A$2:$A$1001, RANDBETWEEN(1, 1000))} -> 45.283555 | F5: {=INDEX(machine_failure_dataset1!$A$2:$A$1001, RANDBETWEEN(1, 1000))} -> 60.906125 | G5: {=INDEX(machine_failure_dataset1!$A$2:$A$1001, RANDBETWEEN(1, 1000))} -> 77.916627 | H5: {=INDEX(machine_failure_dataset1!$A$2:$A$1001, RANDBETWEEN(1, 1000))} -> 73.241664 | ... T5: {=INDEX(machine_failure_dataset1!$A$2:$A$1001, RANDBETWEEN(1, 1000))} -> 69.102643 | U5: =AVERAGE(A5:T5) -> 67.964979
A6: {=INDEX(machine_failure_dataset1!$A$2:$A$1001, RANDBETWEEN(1, 1000))} -> 72.088636 | B6: {=INDEX(machine_failure_dataset1!$A$2:$A$1001, RANDBETWEEN(1, 1000))} -> 69.920274 | C6: {=INDEX(machine_failure_dataset1!$A$2:$A$1001, RANDBETWEEN(1, 1000))} -> 67.978073 | D6: {=INDEX(machine_failure_dataset1!$A$2:$A$1001, RANDBETWEEN(1, 1000))} -> 63.23078 | E6: {=INDEX(machine_failure_dataset1!$A$2:$A$1001, RANDBETWEEN(1, 1000))} -> 69.672467 | F6: {=INDEX(machine_failure_dataset1!$A$2:$A$1001, RANDBETWEEN(1, 1000))} -> 72.897749 | G6: {=INDEX(machine_failure_dataset1!$A$2:$A$1001, RANDBETWEEN(1, 1000))} -> 72.322537 | H6: {=INDEX(machine_failure_dataset1!$A$2:$A$1001, RANDBETWEEN(1, 1000))} -> 66.654988 | ... T6: {=INDEX(machine_failure_dataset1!$A$2:$A$1001, RANDBETWEEN(1, 1000))} -> 70.675282 | U6: =AVERAGE(A6:T6) -> 71.5104
A7: {=INDEX(machine_failure_dataset1!$A$2:$A$1001, RANDBETWEEN(1, 1000))} -> 70.480849 | B7: {=INDEX(machine_failure_dataset1!$A$2:$A$1001, RANDBETWEEN(1, 1000))} -> 45.761207 | C7: {=INDEX(machine_failure_dataset1!$A$2:$A$1001, RANDBETWEEN(1, 1000))} -> 56.401439 | D7: {=INDEX(machine_failure_dataset1!$A$2:$A$1001, RANDBETWEEN(1, 1000))} -> 76.81953 | E7: {=INDEX(machine_failure_dataset1!$A$2:$A$1001, RANDBETWEEN(1, 1000))} -> 73.475817 | F7: {=INDEX(machine_failure_dataset1!$A$2:$A$1001, RANDBETWEEN(1, 1000))} -> 63.534271 | G7: {=INDEX(machine_failure_dataset1!$A$2:$A$1001, RANDBETWEEN(1, 1000))} -> 71.307406 | H7: {=INDEX(machine_failure_dataset1!$A$2:$A$1001, RANDBETWEEN(1, 1000))} -> 62.998792 | ... T7: {=INDEX(machine_failure_dataset1!$A$2:$A$1001, RANDBETWEEN(1, 1000))} -> 67.654129 | U7: =AVERAGE(A7:T7) -> 67.395918
A8: {=INDEX(machine_failure_dataset1!$A$2:$A$1001, RANDBETWEEN(1, 1000))} -> 77.910319 | B8: {=INDEX(machine_failure_dataset1!$A$2:$A$1001, RANDBETWEEN(1, 1000))} -> 69.298343 | C8: {=INDEX(machine_failure_dataset1!$A$2:$A$1001, RANDBETWEEN(1, 1000))} -> 70.698021 | D8: {=INDEX(machine_failure_dataset1!$A$2:$A$1001, RANDBETWEEN(1, 1000))} -> 68.482149 | E8: {=INDEX(machine_failure_dataset1!$A$2:$A$1001, RANDBETWEEN(1, 1000))} -> 60.778347 | F8: {=INDEX(machine_failure_dataset1!$A$2:$A$1001, RANDBETWEEN(1, 1000))} -> 73.824097 | G8: {=INDEX(machine_failure_dataset1!$A$2:$A$1001, RANDBETWEEN(1, 1000))} -> 74.919192 | H8: {=INDEX(machine_failure_dataset1!$A$2:$A$1001, RANDBETWEEN(1, 1000))} -> 55.924883 | ... T8: {=INDEX(machine_failure_dataset1!$A$2:$A$1001, RANDBETWEEN(1, 1000))} -> 74.129315 | U8: =AVERAGE(A8:T8) -> 68.669076
A9: {=INDEX(machine_failure_dataset1!$A$2:$A$1001, RANDBETWEEN(1, 1000))} -> 65.212514 | B9: {=INDEX(machine_failure_dataset1!$A$2:$A$1001, RANDBETWEEN(1, 1000))} -> 69.271711 | C9: {=INDEX(machine_failure_dataset1!$A$2:$A$1001, RANDBETWEEN(1, 1000))} -> 78.294056 | D9: {=INDEX(machine_failure_dataset1!$A$2:$A$1001, RANDBETWEEN(1, 1000))} -> 78.225449 | E9: {=INDEX(machine_failure_dataset1!$A$2:$A$1001, RANDBETWEEN(1, 1000))} -> 63.481639 | F9: {=INDEX(machine_failure_dataset1!$A$2:$A$1001, RANDBETWEEN(1, 1000))} -> 73.61636 | G9: {=INDEX(machine_failure_dataset1!$A$2:$A$1001, RANDBETWEEN(1, 1000))} -> 70.73318 | H9: {=INDEX(machine_failure_dataset1!$A$2:$A$1001, RANDBETWEEN(1, 1000))} -> 68.929696 | ... T9: {=INDEX(machine_failure_dataset1!$A$2:$A$1001, RANDBETWEEN(1, 1000))} -> 71.958453 | U9: =AVERAGE(A9:T9) -> 69.250437
A10: {=INDEX(machine_failure_dataset1!$A$2:$A$1001, RANDBETWEEN(1, 1000))} -> 66.897332 | B10: {=INDEX(machine_failure_dataset1!$A$2:$A$1001, RANDBETWEEN(1, 1000))} -> 72.670503 | C10: {=INDEX(machine_failure_dataset1!$A$2:$A$1001, RANDBETWEEN(1, 1000))} -> 76.329318 | D10: {=INDEX(machine_failure_dataset1!$A$2:$A$1001, RANDBETWEEN(1, 1000))} -> 69.623653 | E10: {=INDEX(machine_failure_dataset1!$A$2:$A$1001, RANDBETWEEN(1, 1000))} -> 63.534271 | F10: {=INDEX(machine_failure_dataset1!$A$2:$A$1001, RANDBETWEEN(1, 1000))} -> 77.746341 | G10: {=INDEX(machine_failure_dataset1!$A$2:$A$1001, RANDBETWEEN(1, 1000))} -> 73.772119 | H10: {=INDEX(machine_failure_dataset1!$A$2:$A$1001, RANDBETWEEN(1, 1000))} -> 76.116763 | ... T10: {=INDEX(machine_failure_dataset1!$A$2:$A$1001, RANDBETWEEN(1, 1000))} -> 55.144396 | U10: =AVERAGE(A10:T10) -> 71.492129
A11: {=INDEX(machine_failure_dataset1!$A$2:$A$1001, RANDBETWEEN(1, 1000))} -> 78.219025 | B11: {=INDEX(machine_failure_dataset1!$A$2:$A$1001, RANDBETWEEN(1, 1000))} -> 61.104856 | C11: {=INDEX(machine_failure_dataset1!$A$2:$A$1001, RANDBETWEEN(1, 1000))} -> 74.567532 | D11: {=INDEX(machine_failure_dataset1!$A$2:$A$1001, RANDBETWEEN(1, 1000))} -> 80.035329 | E11: {=INDEX(machine_failure_dataset1!$A$2:$A$1001, RANDBETWEEN(1, 1000))} -> 72.544208 | F11: {=INDEX(machine_failure_dataset1!$A$2:$A$1001, RANDBETWEEN(1, 1000))} -> 62.216953 | G11: {=INDEX(machine_failure_dataset1!$A$2:$A$1001, RANDBETWEEN(1, 1000))} -> 88.657745 | H11: {=INDEX(machine_failure_dataset1!$A$2:$A$1001, RANDBETWEEN(1, 1000))} -> 69.653151 | ... T11: {=INDEX(machine_failure_dataset1!$A$2:$A$1001, RANDBETWEEN(1, 1000))} -> 72.02923 | U11: =AVERAGE(A11:T11) -> 69.420364
A12: {=INDEX(machine_failure_dataset1!$A$2:$A$1001, RANDBETWEEN(1, 1000))} -> 75.597904 | B12: {=INDEX(machine_failure_dataset1!$A$2:$A$1001, RANDBETWEEN(1, 1000))} -> 59.734847 | C12: {=INDEX(machine_failure_dataset1!$A$2:$A$1001, RANDBETWEEN(1, 1000))} -> 88.761708 | D12: {=INDEX(machine_failure_dataset1!$A$2:$A$1001, RANDBETWEEN(1, 1000))} -> 71.910991 | E12: {=INDEX(machine_failure_dataset1!$A$2:$A$1001, RANDBETWEEN(1, 1000))} -> 81.890165 | F12: {=INDEX(machine_failure_dataset1!$A$2:$A$1001, RANDBETWEEN(1, 1000))} -> 78.995999 | G12: {=INDEX(machine_failure_dataset1!$A$2:$A$1001, RANDBETWEEN(1, 1000))} -> 69.623653 | H12: {=INDEX(machine_failure_dataset1!$A$2:$A$1001, RANDBETWEEN(1, 1000))} -> 55.214138 | ... T12: {=INDEX(machine_failure_dataset1!$A$2:$A$1001, RANDBETWEEN(1, 1000))} -> 65.538166 | U12: =AVERAGE(A12:T12) -> 71.789796
A13: {=INDEX(machine_failure_dataset1!$A$2:$A$1001, RANDBETWEEN(1, 1000))} -> 75.770721 | B13: {=INDEX(machine_failure_dataset1!$A$2:$A$1001, RANDBETWEEN(1, 1000))} -> 75.770721 | C13: {=INDEX(machine_failure_dataset1!$A$2:$A$1001, RANDBETWEEN(1, 1000))} -> 51.591258 | D13: {=INDEX(machine_failure_dataset1!$A$2:$A$1001, RANDBETWEEN(1, 1000))} -> 90.102045 | E13: {=INDEX(machine_failure_dataset1!$A$2:$A$1001, RANDBETWEEN(1, 1000))} -> 85.230299 | F13: {=INDEX(machine_failure_dataset1!$A$2:$A$1001, RANDBETWEEN(1, 1000))} -> 73.072995 | G13: {=INDEX(machine_failure_dataset1!$A$2:$A$1001, RANDBETWEEN(1, 1000))} -> 76.327819 | H13: {=INDEX(machine_failure_dataset1!$A$2:$A$1001, RANDBETWEEN(1, 1000))} -> 76.81953 | ... T13: {=INDEX(machine_failure_dataset1!$A$2:$A$1001, RANDBETWEEN(1, 1000))} -> 80.531529 | U13: =AVERAGE(A13:T13) -> 70.594805
... A101: {=INDEX(machine_failure_dataset1!$A$2:$A$1001, RANDBETWEEN(1, 1000))} -> 85.475052 | B101: {=INDEX(machine_failure_dataset1!$A$2:$A$1001, RANDBETWEEN(1, 1000))} -> 73.24084 | C101: {=INDEX(machine_failure_dataset1!$A$2:$A$1001, RANDBETWEEN(1, 1000))} -> 78.773623 | D101: {=INDEX(machine_failure_dataset1!$A$2:$A$1001, RANDBETWEEN(1, 1000))} -> 52.974164 | E101: {=INDEX(machine_failure_dataset1!$A$2:$A$1001, RANDBETWEEN(1, 1000))} -> 78.303358 | F101: {=INDEX(machine_failure_dataset1!$A$2:$A$1001, RANDBETWEEN(1, 1000))} -> 57.630493 | G101: {=INDEX(machine_failure_dataset1!$A$2:$A$1001, RANDBETWEEN(1, 1000))} -> 81.033019 | H101: {=INDEX(machine_failure_dataset1!$A$2:$A$1001, RANDBETWEEN(1, 1000))} -> 67.790358 | ... T101: {=INDEX(machine_failure_dataset1!$A$2:$A$1001, RANDBETWEEN(1, 1000))} -> 80.571222 | U101: =AVERAGE(A101:T101) -> 69.610363

Sheet Sampling Distribution (n=50)
AO1: 100 Samples of 50 | AY1: Mean
A2: {=INDEX(machine_failure_dataset1!$A$2:$A$1001, RANDBETWEEN(1, 1000))} -> 60.103952 | B2: {=INDEX(machine_failure_dataset1!$A$2:$A$1001, RANDBETWEEN(1, 1000))} -> 94.632421 | C2: {=INDEX(machine_failure_dataset1!$A$2:$A$1001, RANDBETWEEN(1, 1000))} -> 78.204822 | D2: {=INDEX(machine_failure_dataset1!$A$2:$A$1001, RANDBETWEEN(1, 1000))} -> 64.00625 | E2: {=INDEX(machine_failure_dataset1!$A$2:$A$1001, RANDBETWEEN(1, 1000))} -> 60.241267 | F2: {=INDEX(machine_failure_dataset1!$A$2:$A$1001, RANDBETWEEN(1, 1000))} -> 67.188997 | G2: {=INDEX(machine_failure_dataset1!$A$2:$A$1001, RANDBETWEEN(1, 1000))} -> 55.924883 | H2: {=INDEX(machine_failure_dataset1!$A$2:$A$1001, RANDBETWEEN(1, 1000))} -> 85.774533 | ... AX2: {=INDEX(machine_failure_dataset1!$A$2:$A$1001, RANDBETWEEN(1, 1000))} -> 63.47376 | AY2: =AVERAGE(A2:AX2) -> 71.281466
A3: {=INDEX(machine_failure_dataset1!$A$2:$A$1001, RANDBETWEEN(1, 1000))} -> 80.571222 | B3: {=INDEX(machine_failure_dataset1!$A$2:$A$1001, RANDBETWEEN(1, 1000))} -> 63.373762 | C3: {=INDEX(machine_failure_dataset1!$A$2:$A$1001, RANDBETWEEN(1, 1000))} -> 87.654542 | D3: {=INDEX(machine_failure_dataset1!$A$2:$A$1001, RANDBETWEEN(1, 1000))} -> 78.204822 | E3: {=INDEX(machine_failure_dataset1!$A$2:$A$1001, RANDBETWEEN(1, 1000))} -> 76.228499 | F3: {=INDEX(machine_failure_dataset1!$A$2:$A$1001, RANDBETWEEN(1, 1000))} -> 82.012139 | G3: {=INDEX(machine_failure_dataset1!$A$2:$A$1001, RANDBETWEEN(1, 1000))} -> 59.291075 | H3: {=INDEX(machine_failure_dataset1!$A$2:$A$1001, RANDBETWEEN(1, 1000))} -> 73.112502 | ... AX3: {=INDEX(machine_failure_dataset1!$A$2:$A$1001, RANDBETWEEN(1, 1000))} -> 78.254163 | AY3: =AVERAGE(A3:AX3) -> 72.751836
A4: {=INDEX(machine_failure_dataset1!$A$2:$A$1001, RANDBETWEEN(1, 1000))} -> 69.623653 | B4: {=INDEX(machine_failure_dataset1!$A$2:$A$1001, RANDBETWEEN(1, 1000))} -> 68.843517 | C4: {=INDEX(machine_failure_dataset1!$A$2:$A$1001, RANDBETWEEN(1, 1000))} -> 76.427228 | D4: {=INDEX(machine_failure_dataset1!$A$2:$A$1001, RANDBETWEEN(1, 1000))} -> 69.835771 | E4: {=INDEX(machine_failure_dataset1!$A$2:$A$1001, RANDBETWEEN(1, 1000))} -> 67.50964 | F4: {=INDEX(machine_failure_dataset1!$A$2:$A$1001, RANDBETWEEN(1, 1000))} -> 61.793177 | G4: {=INDEX(machine_failure_dataset1!$A$2:$A$1001, RANDBETWEEN(1, 1000))} -> 74.040509 | H4: {=INDEX(machine_failure_dataset1!$A$2:$A$1001, RANDBETWEEN(1, 1000))} -> 53.075354 | ... AX4: {=INDEX(machine_failure_dataset1!$A$2:$A$1001, RANDBETWEEN(1, 1000))} -> 62.801558 | AY4: =AVERAGE(A4:AX4) -> 68.986062
A5: {=INDEX(machine_failure_dataset1!$A$2:$A$1001, RANDBETWEEN(1, 1000))} -> 88.314588 | B5: {=INDEX(machine_failure_dataset1!$A$2:$A$1001, RANDBETWEEN(1, 1000))} -> 59.958592 | C5: {=INDEX(machine_failure_dataset1!$A$2:$A$1001, RANDBETWEEN(1, 1000))} -> 65.557067 | D5: {=INDEX(machine_failure_dataset1!$A$2:$A$1001, RANDBETWEEN(1, 1000))} -> 62.408673 | E5: {=INDEX(machine_failure_dataset1!$A$2:$A$1001, RANDBETWEEN(1, 1000))} -> 85.774533 | F5: {=INDEX(machine_failure_dataset1!$A$2:$A$1001, RANDBETWEEN(1, 1000))} -> 73.109076 | G5: {=INDEX(machine_failure_dataset1!$A$2:$A$1001, RANDBETWEEN(1, 1000))} -> 59.9838 | H5: {=INDEX(machine_failure_dataset1!$A$2:$A$1001, RANDBETWEEN(1, 1000))} -> 51.591258 | ... AX5: {=INDEX(machine_failure_dataset1!$A$2:$A$1001, RANDBETWEEN(1, 1000))} -> 80.538021 | AY5: =AVERAGE(A5:AX5) -> 68.328986
A6: {=INDEX(machine_failure_dataset1!$A$2:$A$1001, RANDBETWEEN(1, 1000))} -> 59.376963 | B6: {=INDEX(machine_failure_dataset1!$A$2:$A$1001, RANDBETWEEN(1, 1000))} -> 84.415686 | C6: {=INDEX(machine_failure_dataset1!$A$2:$A$1001, RANDBETWEEN(1, 1000))} -> 73.75698 | D6: {=INDEX(machine_failure_dataset1!$A$2:$A$1001, RANDBETWEEN(1, 1000))} -> 78.303358 | E6: {=INDEX(machine_failure_dataset1!$A$2:$A$1001, RANDBETWEEN(1, 1000))} -> 68.912399 | F6: {=INDEX(machine_failure_dataset1!$A$2:$A$1001, RANDBETWEEN(1, 1000))} -> 69.790984 | G6: {=INDEX(machine_failure_dataset1!$A$2:$A$1001, RANDBETWEEN(1, 1000))} -> 81.950466 | H6: {=INDEX(machine_failure_dataset1!$A$2:$A$1001, RANDBETWEEN(1, 1000))} -> 69.522886 | ... AX6: {=INDEX(machine_failure_dataset1!$A$2:$A$1001, RANDBETWEEN(1, 1000))} -> 69.653151 | AY6: =AVERAGE(A6:AX6) -> 71.102505
A7: {=INDEX(machine_failure_dataset1!$A$2:$A$1001, RANDBETWEEN(1, 1000))} -> 83.556379 | B7: {=INDEX(machine_failure_dataset1!$A$2:$A$1001, RANDBETWEEN(1, 1000))} -> 76.329318 | C7: {=INDEX(machine_failure_dataset1!$A$2:$A$1001, RANDBETWEEN(1, 1000))} -> 73.41152 | D7: {=INDEX(machine_failure_dataset1!$A$2:$A$1001, RANDBETWEEN(1, 1000))} -> 87.547942 | E7: {=INDEX(machine_failure_dataset1!$A$2:$A$1001, RANDBETWEEN(1, 1000))} -> 64.230963 | F7: {=INDEX(machine_failure_dataset1!$A$2:$A$1001, RANDBETWEEN(1, 1000))} -> 85.646437 | G7: {=INDEX(machine_failure_dataset1!$A$2:$A$1001, RANDBETWEEN(1, 1000))} -> 76.256673 | H7: {=INDEX(machine_failure_dataset1!$A$2:$A$1001, RANDBETWEEN(1, 1000))} -> 64.817298 | ... AX7: {=INDEX(machine_failure_dataset1!$A$2:$A$1001, RANDBETWEEN(1, 1000))} -> 80.571222 | AY7: =AVERAGE(A7:AX7) -> 71.143296
A8: {=INDEX(machine_failure_dataset1!$A$2:$A$1001, RANDBETWEEN(1, 1000))} -> 68.617357 | B8: {=INDEX(machine_failure_dataset1!$A$2:$A$1001, RANDBETWEEN(1, 1000))} -> 60.253183 | C8: {=INDEX(machine_failure_dataset1!$A$2:$A$1001, RANDBETWEEN(1, 1000))} -> 50.479122 | D8: {=INDEX(machine_failure_dataset1!$A$2:$A$1001, RANDBETWEEN(1, 1000))} -> 80.318445 | E8: {=INDEX(machine_failure_dataset1!$A$2:$A$1001, RANDBETWEEN(1, 1000))} -> 68.096613 | F8: {=INDEX(machine_failure_dataset1!$A$2:$A$1001, RANDBETWEEN(1, 1000))} -> 54.8063 | G8: {=INDEX(machine_failure_dataset1!$A$2:$A$1001, RANDBETWEEN(1, 1000))} -> 52.750822 | H8: {=INDEX(machine_failure_dataset1!$A$2:$A$1001, RANDBETWEEN(1, 1000))} -> 80.538021 | ... AX8: {=INDEX(machine_failure_dataset1!$A$2:$A$1001, RANDBETWEEN(1, 1000))} -> 88.522782 | AY8: =AVERAGE(A8:AX8) -> 67.489777
A9: {=INDEX(machine_failure_dataset1!$A$2:$A$1001, RANDBETWEEN(1, 1000))} -> 54.768131 | B9: {=INDEX(machine_failure_dataset1!$A$2:$A$1001, RANDBETWEEN(1, 1000))} -> 81.794401 | C9: {=INDEX(machine_failure_dataset1!$A$2:$A$1001, RANDBETWEEN(1, 1000))} -> 84.960443 | D9: {=INDEX(machine_failure_dataset1!$A$2:$A$1001, RANDBETWEEN(1, 1000))} -> 58.490064 | E9: {=INDEX(machine_failure_dataset1!$A$2:$A$1001, RANDBETWEEN(1, 1000))} -> 74.040509 | F9: {=INDEX(machine_failure_dataset1!$A$2:$A$1001, RANDBETWEEN(1, 1000))} -> 88.314588 | G9: {=INDEX(machine_failure_dataset1!$A$2:$A$1001, RANDBETWEEN(1, 1000))} -> 65.365823 | H9: {=INDEX(machine_failure_dataset1!$A$2:$A$1001, RANDBETWEEN(1, 1000))} -> 80.889506 | ... AX9: {=INDEX(machine_failure_dataset1!$A$2:$A$1001, RANDBETWEEN(1, 1000))} -> 87.654542 | AY9: =AVERAGE(A9:AX9) -> 70.623988
A10: {=INDEX(machine_failure_dataset1!$A$2:$A$1001, RANDBETWEEN(1, 1000))} -> 95.600845 | B10: {=INDEX(machine_failure_dataset1!$A$2:$A$1001, RANDBETWEEN(1, 1000))} -> 70.469806 | C10: {=INDEX(machine_failure_dataset1!$A$2:$A$1001, RANDBETWEEN(1, 1000))} -> 77.003099 | D10: {=INDEX(machine_failure_dataset1!$A$2:$A$1001, RANDBETWEEN(1, 1000))} -> 84.799441 | E10: {=INDEX(machine_failure_dataset1!$A$2:$A$1001, RANDBETWEEN(1, 1000))} -> 91.221562 | F10: {=INDEX(machine_failure_dataset1!$A$2:$A$1001, RANDBETWEEN(1, 1000))} -> 74.567532 | G10: {=INDEX(machine_failure_dataset1!$A$2:$A$1001, RANDBETWEEN(1, 1000))} -> 66.572855 | H10: {=INDEX(machine_failure_dataset1!$A$2:$A$1001, RANDBETWEEN(1, 1000))} -> 65.280681 | ... AX10: {=INDEX(machine_failure_dataset1!$A$2:$A$1001, RANDBETWEEN(1, 1000))} -> 61.830643 | AY10: =AVERAGE(A10:AX10) -> 72.354741
A11: {=INDEX(machine_failure_dataset1!$A$2:$A$1001, RANDBETWEEN(1, 1000))} -> 63.180158 | B11: {=INDEX(machine_failure_dataset1!$A$2:$A$1001, RANDBETWEEN(1, 1000))} -> 88.467073 | C11: {=INDEX(machine_failure_dataset1!$A$2:$A$1001, RANDBETWEEN(1, 1000))} -> 73.577874 | D11: {=INDEX(machine_failure_dataset1!$A$2:$A$1001, RANDBETWEEN(1, 1000))} -> 76.324077 | E11: {=INDEX(machine_failure_dataset1!$A$2:$A$1001, RANDBETWEEN(1, 1000))} -> 64.106352 | F11: {=INDEX(machine_failure_dataset1!$A$2:$A$1001, RANDBETWEEN(1, 1000))} -> 71.329697 | G11: {=INDEX(machine_failure_dataset1!$A$2:$A$1001, RANDBETWEEN(1, 1000))} -> 61.777796 | H11: {=INDEX(machine_failure_dataset1!$A$2:$A$1001, RANDBETWEEN(1, 1000))} -> 65.544975 | ... AX11: {=INDEX(machine_failure_dataset1!$A$2:$A$1001, RANDBETWEEN(1, 1000))} -> 64.292537 | AY11: =AVERAGE(A11:AX11) -> 69.412138
A12: {=INDEX(machine_failure_dataset1!$A$2:$A$1001, RANDBETWEEN(1, 1000))} -> 95.269324 | B12: {=INDEX(machine_failure_dataset1!$A$2:$A$1001, RANDBETWEEN(1, 1000))} -> 85.931866 | C12: {=INDEX(machine_failure_dataset1!$A$2:$A$1001, RANDBETWEEN(1, 1000))} -> 65.790155 | D12: {=INDEX(machine_failure_dataset1!$A$2:$A$1001, RANDBETWEEN(1, 1000))} -> 55.915387 | E12: {=INDEX(machine_failure_dataset1!$A$2:$A$1001, RANDBETWEEN(1, 1000))} -> 62.326524 | F12: {=INDEX(machine_failure_dataset1!$A$2:$A$1001, RANDBETWEEN(1, 1000))} -> 67.474318 | G12: {=INDEX(machine_failure_dataset1!$A$2:$A$1001, RANDBETWEEN(1, 1000))} -> 65.393612 | H12: {=INDEX(machine_failure_dataset1!$A$2:$A$1001, RANDBETWEEN(1, 1000))} -> 77.140005 | ... AX12: {=INDEX(machine_failure_dataset1!$A$2:$A$1001, RANDBETWEEN(1, 1000))} -> 61.243817 | AY12: =AVERAGE(A12:AX12) -> 70.026695
A13: {=INDEX(machine_failure_dataset1!$A$2:$A$1001, RANDBETWEEN(1, 1000))} -> 75.193465 | B13: {=INDEX(machine_failure_dataset1!$A$2:$A$1001, RANDBETWEEN(1, 1000))} -> 51.591258 | C13: {=INDEX(machine_failure_dataset1!$A$2:$A$1001, RANDBETWEEN(1, 1000))} -> 79.154021 | D13: {=INDEX(machine_failure_dataset1!$A$2:$A$1001, RANDBETWEEN(1, 1000))} -> 76.33919 | E13: {=INDEX(machine_failure_dataset1!$A$2:$A$1001, RANDBETWEEN(1, 1000))} -> 64.106352 | F13: {=INDEX(machine_failure_dataset1!$A$2:$A$1001, RANDBETWEEN(1, 1000))} -> 64.359214 | G13: {=INDEX(machine_failure_dataset1!$A$2:$A$1001, RANDBETWEEN(1, 1000))} -> 64.375332 | H13: {=INDEX(machine_failure_dataset1!$A$2:$A$1001, RANDBETWEEN(1, 1000))} -> 73.269274 | ... AX13: {=INDEX(machine_failure_dataset1!$A$2:$A$1001, RANDBETWEEN(1, 1000))} -> 60.330239 | AY13: =AVERAGE(A13:AX13) -> 68.747415
... A101: {=INDEX(machine_failure_dataset1!$A$2:$A$1001, RANDBETWEEN(1, 1000))} -> 73.711459 | B101: {=INDEX(machine_failure_dataset1!$A$2:$A$1001, RANDBETWEEN(1, 1000))} -> 76.206721 | C101: {=INDEX(machine_failure_dataset1!$A$2:$A$1001, RANDBETWEEN(1, 1000))} -> 70.68563 | D101: {=INDEX(machine_failure_dataset1!$A$2:$A$1001, RANDBETWEEN(1, 1000))} -> 60.767668 | E101: {=INDEX(machine_failure_dataset1!$A$2:$A$1001, RANDBETWEEN(1, 1000))} -> 76.815007 | F101: {=INDEX(machine_failure_dataset1!$A$2:$A$1001, RANDBETWEEN(1, 1000))} -> 55.692249 | G101: {=INDEX(machine_failure_dataset1!$A$2:$A$1001, RANDBETWEEN(1, 1000))} -> 85.230299 | H101: {=INDEX(machine_failure_dataset1!$A$2:$A$1001, RANDBETWEEN(1, 1000))} -> 78.225449 | ... AX101: {=INDEX(machine_failure_dataset1!$A$2:$A$1001, RANDBETWEEN(1, 1000))} -> 76.621307 | AY101: =AVERAGE(A101:AX101) -> 72.09852
